ERROR:root:Исключение:
Traceback (most recent call last):
  File "C:\Users\Ром\Documents\Urban_1\Homework\temp.py", line 10, in <module>
    faulty_function()
  File "C:\Users\Ром\Documents\Urban_1\Homework\temp.py", line 7, in faulty_function
    return 1 / 0
           ~~^~~
ZeroDivisionError: division by zero
